[SocketIO] Registering WebSocket event handlers...
[SocketIO] Event handlers registered successfully
 * Serving Flask app 'app'
 * Debug mode: off
[31m[1mWARNING: This is a development server. Do not use it in a production deployment. Use a production WSGI server instead.[0m
 * Running on http://127.0.0.1:5000
[33mPress CTRL+C to quit[0m
127.0.0.1 - - [29/Oct/2025 19:07:56] "GET /profiles/login?id=8197eb95-0e3a-4ee0-abed-110fd643084a&vscodeBrowserReqId=1761800876483 HTTP/1.1" 200 -
127.0.0.1 - - [29/Oct/2025 19:08:46] "[32mPOST /profiles/login HTTP/1.1[0m" 302 -
127.0.0.1 - - [29/Oct/2025 19:08:46] "[32mGET /profiles/map HTTP/1.1[0m" 302 -
127.0.0.1 - - [29/Oct/2025 19:08:46] "GET /profiles/login HTTP/1.1" 200 -
127.0.0.1 - - [29/Oct/2025 19:08:55] "[32mPOST /profiles/login HTTP/1.1[0m" 302 -
127.0.0.1 - - [29/Oct/2025 19:08:55] "[32mGET /profiles/map HTTP/1.1[0m" 302 -
127.0.0.1 - - [29/Oct/2025 19:08:55] "GET /profiles/login HTTP/1.1" 200 -
127.0.0.1 - - [29/Oct/2025 19:09:00] "[33mGET /profiles/maps?id=8197eb95-0e3a-4ee0-abed-110fd643084a&vscodeBrowserReqId=1761800940466 HTTP/1.1[0m" 404 -
127.0.0.1 - - [29/Oct/2025 19:09:01] "[32mGET /profiles/map?id=8197eb95-0e3a-4ee0-abed-110fd643084a&vscodeBrowserReqId=1761800941519 HTTP/1.1[0m" 302 -
127.0.0.1 - - [29/Oct/2025 19:09:01] "GET /profiles/login HTTP/1.1" 200 -
127.0.0.1 - - [29/Oct/2025 19:09:08] "[32mPOST /profiles/login HTTP/1.1[0m" 302 -
127.0.0.1 - - [29/Oct/2025 19:09:08] "[32mGET /profiles/map HTTP/1.1[0m" 302 -
127.0.0.1 - - [29/Oct/2025 19:09:08] "GET /profiles/login HTTP/1.1" 200 -
127.0.0.1 - - [29/Oct/2025 19:09:24] "GET / HTTP/1.1" 200 -
127.0.0.1 - - [29/Oct/2025 19:09:27] "[32mGET /profiles HTTP/1.1[0m" 308 -
127.0.0.1 - - [29/Oct/2025 19:09:27] "GET /profiles/ HTTP/1.1" 200 -
127.0.0.1 - - [29/Oct/2025 19:09:30] "GET /profiles/login HTTP/1.1" 200 -
127.0.0.1 - - [29/Oct/2025 19:09:34] "[32mPOST /profiles/login HTTP/1.1[0m" 302 -
127.0.0.1 - - [29/Oct/2025 19:09:34] "GET /profiles/map HTTP/1.1" 200 -
127.0.0.1 - - [29/Oct/2025 19:09:35] "GET /socket.io/?EIO=4&transport=polling&t=PepXNBV HTTP/1.1" 200 -
127.0.0.1 - - [29/Oct/2025 19:09:35] "POST /socket.io/?EIO=4&transport=polling&t=PepXNBb&sid=g8JFbW-rtCwYGSI2AAAA HTTP/1.1" 200 -
127.0.0.1 - - [29/Oct/2025 19:09:35] "GET /socket.io/?EIO=4&transport=polling&t=PepXNBc&sid=g8JFbW-rtCwYGSI2AAAA HTTP/1.1" 200 -
127.0.0.1 - - [29/Oct/2025 19:09:35] "GET /socket.io/?EIO=4&transport=polling&t=PepXNBh&sid=g8JFbW-rtCwYGSI2AAAA HTTP/1.1" 200 -
Exception in thread Thread-29 (_handle_event_internal):
127.0.0.1 - - [29/Oct/2025 19:09:35] "POST /socket.io/?EIO=4&transport=polling&t=PepXNBi&sid=g8JFbW-rtCwYGSI2AAAA HTTP/1.1" 200 -
Traceback (most recent call last):
  File "/opt/homebrew/Cellar/python@3.14/3.14.0/Frameworks/Python.framework/Versions/3.14/lib/python3.14/threading.py", line 1081, in _bootstrap_inner
    self._context.run(self.run)
    ~~~~~~~~~~~~~~~~~^^^^^^^^^^
  File "/opt/homebrew/Cellar/python@3.14/3.14.0/Frameworks/Python.framework/Versions/3.14/lib/python3.14/threading.py", line 1023, in run
    self._target(*self._args, **self._kwargs)
    ~~~~~~~~~~~~^^^^^^^^^^^^^^^^^^^^^^^^^^^^^
  File "/Users/angeport/Documents/GitHub/Group-Navigation/.venv/lib/python3.14/site-packages/socketio/server.py", line 594, in _handle_event_internal
    r = server._trigger_event(data[0], namespace, sid, *data[1:])
  File "/Users/angeport/Documents/GitHub/Group-Navigation/.venv/lib/python3.14/site-packages/socketio/server.py", line 620, in _trigger_event
    return handler(*args)
  File "/Users/angeport/Documents/GitHub/Group-Navigation/.venv/lib/python3.14/site-packages/flask_socketio/__init__.py", line 292, in _handler
    return self._handle_event(handler, message, real_ns, sid,
           ~~~~~~~~~~~~~~~~~~^^^^^^^^^^^^^^^^^^^^^^^^^^^^^^^^
                              *args)
                              ^^^^^^
  File "/Users/angeport/Documents/GitHub/Group-Navigation/.venv/lib/python3.14/site-packages/flask_socketio/__init__.py", line 835, in _handle_event
    ret = handler(*args)
  File "/Users/angeport/Documents/GitHub/Group-Navigation/routes.py", line 763, in on_join_tracking
    sio.emit('user_count', len(connected_users), broadcast=True)
    ~~~~~~~~^^^^^^^^^^^^^^^^^^^^^^^^^^^^^^^^^^^^^^^^^^^^^^^^^^^^
  File "/Users/angeport/Documents/GitHub/Group-Navigation/.venv/lib/python3.14/site-packages/flask_socketio/__init__.py", line 472, in emit
    self.server.emit(event, *args, namespace=namespace, to=to,
    ~~~~~~~~~~~~~~~~^^^^^^^^^^^^^^^^^^^^^^^^^^^^^^^^^^^^^^^^^^
                     skip_sid=skip_sid, callback=callback, **kwargs)
                     ^^^^^^^^^^^^^^^^^^^^^^^^^^^^^^^^^^^^^^^^^^^^^^^
TypeError: Server.emit() got an unexpected keyword argument 'broadcast'
Exception in thread Thread-31 (_handle_event_internal):
Traceback (most recent call last):
  File "/opt/homebrew/Cellar/python@3.14/3.14.0/Frameworks/Python.framework/Versions/3.14/lib/python3.14/threading.py", line 1081, in _bootstrap_inner
    self._context.run(self.run)
    ~~~~~~~~~~~~~~~~~^^^^^^^^^^
  File "/opt/homebrew/Cellar/python@3.14/3.14.0/Frameworks/Python.framework/Versions/3.14/lib/python3.14/threading.py", line 1023, in run
    self._target(*self._args, **self._kwargs)
    ~~~~~~~~~~~~^^^^^^^^^^^^^^^^^^^^^^^^^^^^^
  File "/Users/angeport/Documents/GitHub/Group-Navigation/.venv/lib/python3.14/site-packages/socketio/server.py", line 594, in _handle_event_internal
    r = server._trigger_event(data[0], namespace, sid, *data[1:])
  File "/Users/angeport/Documents/GitHub/Group-Navigation/.venv/lib/python3.14/site-packages/socketio/server.py", line 620, in _trigger_event
    return handler(*args)
  File "/Users/angeport/Documents/GitHub/Group-Navigation/.venv/lib/python3.14/site-packages/flask_socketio/__init__.py", line 292, in _handler
    return self._handle_event(handler, message, real_ns, sid,
           ~~~~~~~~~~~~~~~~~~^^^^^^^^^^^^^^^^^^^^^^^^^^^^^^^^
                              *args)
                              ^^^^^^
  File "/Users/angeport/Documents/GitHub/Group-Navigation/.venv/lib/python3.14/site-packages/flask_socketio/__init__.py", line 835, in _handle_event
    ret = handler(*args)
  File "/Users/angeport/Documents/GitHub/Group-Navigation/routes.py", line 801, in on_update_location
    sio.emit('location_update', {
    ~~~~~~~~^^^^^^^^^^^^^^^^^^^^^
        'user_id': user_id,
        ^^^^^^^^^^^^^^^^^^^
    ...<3 lines>...
        'longitude': longitude
        ^^^^^^^^^^^^^^^^^^^^^^
    }, broadcast=True)
    ^^^^^^^^^^^^^^^^^^
  File "/Users/angeport/Documents/GitHub/Group-Navigation/.venv/lib/python3.14/site-packages/flask_socketio/__init__.py", line 472, in emit
    self.server.emit(event, *args, namespace=namespace, to=to,
    ~~~~~~~~~~~~~~~~^^^^^^^^^^^^^^^^^^^^^^^^^^^^^^^^^^^^^^^^^^
                     skip_sid=skip_sid, callback=callback, **kwargs)
                     ^^^^^^^^^^^^^^^^^^^^^^^^^^^^^^^^^^^^^^^^^^^^^^^
TypeError: Server.emit() got an unexpected keyword argument 'broadcast'
Exception in thread Thread-32 (_handle_event_internal):
Traceback (most recent call last):
  File "/opt/homebrew/Cellar/python@3.14/3.14.0/Frameworks/Python.framework/Versions/3.14/lib/python3.14/threading.py", line 1081, in _bootstrap_inner
    self._context.run(self.run)
    ~~~~~~~~~~~~~~~~~^^^^^^^^^^
  File "/opt/homebrew/Cellar/python@3.14/3.14.0/Frameworks/Python.framework/Versions/3.14/lib/python3.14/threading.py", line 1023, in run
    self._target(*self._args, **self._kwargs)
    ~~~~~~~~~~~~^^^^^^^^^^^^^^^^^^^^^^^^^^^^^
  File "/Users/angeport/Documents/GitHub/Group-Navigation/.venv/lib/python3.14/site-packages/socketio/server.py", line 594, in _handle_event_internal
    r = server._trigger_event(data[0], namespace, sid, *data[1:])
  File "/Users/angeport/Documents/GitHub/Group-Navigation/.venv/lib/python3.14/site-packages/socketio/server.py", line 620, in _trigger_event
    return handler(*args)
  File "/Users/angeport/Documents/GitHub/Group-Navigation/.venv/lib/python3.14/site-packages/flask_socketio/__init__.py", line 292, in _handler
    return self._handle_event(handler, message, real_ns, sid,
           ~~~~~~~~~~~~~~~~~~^^^^^^^^^^^^^^^^^^^^^^^^^^^^^^^^
                              *args)
                              ^^^^^^
  File "/Users/angeport/Documents/GitHub/Group-Navigation/.venv/lib/python3.14/site-packages/flask_socketio/__init__.py", line 835, in _handle_event
    ret = handler(*args)
  File "/Users/angeport/Documents/GitHub/Group-Navigation/routes.py", line 801, in on_update_location
    sio.emit('location_update', {
    ~~~~~~~~^^^^^^^^^^^^^^^^^^^^^
        'user_id': user_id,
        ^^^^^^^^^^^^^^^^^^^
    ...<3 lines>...
        'longitude': longitude
        ^^^^^^^^^^^^^^^^^^^^^^
    }, broadcast=True)
    ^^^^^^^^^^^^^^^^^^
  File "/Users/angeport/Documents/GitHub/Group-Navigation/.venv/lib/python3.14/site-packages/flask_socketio/__init__.py", line 472, in emit
    self.server.emit(event, *args, namespace=namespace, to=to,
    ~~~~~~~~~~~~~~~~^^^^^^^^^^^^^^^^^^^^^^^^^^^^^^^^^^^^^^^^^^
                     skip_sid=skip_sid, callback=callback, **kwargs)
                     ^^^^^^^^^^^^^^^^^^^^^^^^^^^^^^^^^^^^^^^^^^^^^^^
TypeError: Server.emit() got an unexpected keyword argument 'broadcast'
Exception in thread Thread-33 (_handle_event_internal):
Traceback (most recent call last):
  File "/opt/homebrew/Cellar/python@3.14/3.14.0/Frameworks/Python.framework/Versions/3.14/lib/python3.14/threading.py", line 1081, in _bootstrap_inner
    self._context.run(self.run)
    ~~~~~~~~~~~~~~~~~^^^^^^^^^^
  File "/opt/homebrew/Cellar/python@3.14/3.14.0/Frameworks/Python.framework/Versions/3.14/lib/python3.14/threading.py", line 1023, in run
    self._target(*self._args, **self._kwargs)
    ~~~~~~~~~~~~^^^^^^^^^^^^^^^^^^^^^^^^^^^^^
  File "/Users/angeport/Documents/GitHub/Group-Navigation/.venv/lib/python3.14/site-packages/socketio/server.py", line 594, in _handle_event_internal
    r = server._trigger_event(data[0], namespace, sid, *data[1:])
  File "/Users/angeport/Documents/GitHub/Group-Navigation/.venv/lib/python3.14/site-packages/socketio/server.py", line 620, in _trigger_event
    return handler(*args)
  File "/Users/angeport/Documents/GitHub/Group-Navigation/.venv/lib/python3.14/site-packages/flask_socketio/__init__.py", line 292, in _handler
    return self._handle_event(handler, message, real_ns, sid,
           ~~~~~~~~~~~~~~~~~~^^^^^^^^^^^^^^^^^^^^^^^^^^^^^^^^
                              *args)
                              ^^^^^^
  File "/Users/angeport/Documents/GitHub/Group-Navigation/.venv/lib/python3.14/site-packages/flask_socketio/__init__.py", line 835, in _handle_event
    ret = handler(*args)
  File "/Users/angeport/Documents/GitHub/Group-Navigation/routes.py", line 801, in on_update_location
    sio.emit('location_update', {
    ~~~~~~~~^^^^^^^^^^^^^^^^^^^^^
        'user_id': user_id,
        ^^^^^^^^^^^^^^^^^^^
    ...<3 lines>...
        'longitude': longitude
        ^^^^^^^^^^^^^^^^^^^^^^
    }, broadcast=True)
    ^^^^^^^^^^^^^^^^^^
  File "/Users/angeport/Documents/GitHub/Group-Navigation/.venv/lib/python3.14/site-packages/flask_socketio/__init__.py", line 472, in emit
    self.server.emit(event, *args, namespace=namespace, to=to,
    ~~~~~~~~~~~~~~~~^^^^^^^^^^^^^^^^^^^^^^^^^^^^^^^^^^^^^^^^^^
                     skip_sid=skip_sid, callback=callback, **kwargs)
                     ^^^^^^^^^^^^^^^^^^^^^^^^^^^^^^^^^^^^^^^^^^^^^^^
TypeError: Server.emit() got an unexpected keyword argument 'broadcast'
disconnect handler error
Traceback (most recent call last):
  File "/Users/angeport/Documents/GitHub/Group-Navigation/.venv/lib/python3.14/site-packages/socketio/server.py", line 620, in _trigger_event
    return handler(*args)
  File "/Users/angeport/Documents/GitHub/Group-Navigation/.venv/lib/python3.14/site-packages/flask_socketio/__init__.py", line 292, in _handler
    return self._handle_event(handler, message, real_ns, sid,
           ~~~~~~~~~~~~~~~~~~^^^^^^^^^^^^^^^^^^^^^^^^^^^^^^^^
                              *args)
                              ^^^^^^
  File "/Users/angeport/Documents/GitHub/Group-Navigation/.venv/lib/python3.14/site-packages/flask_socketio/__init__.py", line 835, in _handle_event
    ret = handler(*args)
TypeError: init_socketio.<locals>.on_disconnect() takes 0 positional arguments but 1 was given

During handling of the above exception, another exception occurred:

Traceback (most recent call last):
  File "/Users/angeport/Documents/GitHub/Group-Navigation/.venv/lib/python3.14/site-packages/engineio/server.py", line 450, in run_handler
    return self.handlers[event](*args)
           ~~~~~~~~~~~~~~~~~~~~^^^^^^^
  File "/Users/angeport/Documents/GitHub/Group-Navigation/.venv/lib/python3.14/site-packages/socketio/server.py", line 674, in _handle_eio_disconnect
    self._handle_disconnect(eio_sid, n, reason)
    ~~~~~~~~~~~~~~~~~~~~~~~^^^^^^^^^^^^^^^^^^^^
  File "/Users/angeport/Documents/GitHub/Group-Navigation/.venv/lib/python3.14/site-packages/socketio/server.py", line 571, in _handle_disconnect
    self._trigger_event('disconnect', namespace, sid,
    ~~~~~~~~~~~~~~~~~~~^^^^^^^^^^^^^^^^^^^^^^^^^^^^^^
                        reason or self.reason.CLIENT_DISCONNECT)
                        ^^^^^^^^^^^^^^^^^^^^^^^^^^^^^^^^^^^^^^^^
  File "/Users/angeport/Documents/GitHub/Group-Navigation/.venv/lib/python3.14/site-packages/socketio/server.py", line 624, in _trigger_event
    return handler(*args[:-1])
  File "/Users/angeport/Documents/GitHub/Group-Navigation/.venv/lib/python3.14/site-packages/flask_socketio/__init__.py", line 292, in _handler
    return self._handle_event(handler, message, real_ns, sid,
           ~~~~~~~~~~~~~~~~~~^^^^^^^^^^^^^^^^^^^^^^^^^^^^^^^^
                              *args)
                              ^^^^^^
  File "/Users/angeport/Documents/GitHub/Group-Navigation/.venv/lib/python3.14/site-packages/flask_socketio/__init__.py", line 835, in _handle_event
    ret = handler(*args)
  File "/Users/angeport/Documents/GitHub/Group-Navigation/routes.py", line 826, in on_disconnect
    sio.emit('user_count', len(connected_users), broadcast=True)
    ~~~~~~~~^^^^^^^^^^^^^^^^^^^^^^^^^^^^^^^^^^^^^^^^^^^^^^^^^^^^
  File "/Users/angeport/Documents/GitHub/Group-Navigation/.venv/lib/python3.14/site-packages/flask_socketio/__init__.py", line 472, in emit
    self.server.emit(event, *args, namespace=namespace, to=to,
    ~~~~~~~~~~~~~~~~^^^^^^^^^^^^^^^^^^^^^^^^^^^^^^^^^^^^^^^^^^
                     skip_sid=skip_sid, callback=callback, **kwargs)
                     ^^^^^^^^^^^^^^^^^^^^^^^^^^^^^^^^^^^^^^^^^^^^^^^
TypeError: Server.emit() got an unexpected keyword argument 'broadcast'

During handling of the above exception, another exception occurred:

Traceback (most recent call last):
  File "/Users/angeport/Documents/GitHub/Group-Navigation/.venv/lib/python3.14/site-packages/engineio/server.py", line 456, in run_handler
    return self.handlers[event](args[0])
           ~~~~~~~~~~~~~~~~~~~~^^^^^^^^^
TypeError: Server._handle_eio_disconnect() missing 1 required positional argument: 'reason'
127.0.0.1 - - [29/Oct/2025 19:09:43] "GET /socket.io/?EIO=4&transport=websocket&sid=g8JFbW-rtCwYGSI2AAAA HTTP/1.1" 200 -
127.0.0.1 - - [29/Oct/2025 19:09:43] "GET /profiles/map HTTP/1.1" 200 -
127.0.0.1 - - [29/Oct/2025 19:09:43] "GET /socket.io/?EIO=4&transport=polling&t=PepXPJ9 HTTP/1.1" 200 -
127.0.0.1 - - [29/Oct/2025 19:09:43] "POST /socket.io/?EIO=4&transport=polling&t=PepXPJG&sid=ji8KDF6qjdcXkyCuAAAC HTTP/1.1" 200 -
127.0.0.1 - - [29/Oct/2025 19:09:43] "GET /socket.io/?EIO=4&transport=polling&t=PepXPJH&sid=ji8KDF6qjdcXkyCuAAAC HTTP/1.1" 200 -
Exception in thread Thread-42 (_handle_event_internal):
Traceback (most recent call last):
  File "/opt/homebrew/Cellar/python@3.14/3.14.0/Frameworks/Python.framework/Versions/3.14/lib/python3.14/threading.py", line 1081, in _bootstrap_inner
    self._context.run(self.run)
    ~~~~~~~~~~~~~~~~~^^^^^^^^^^
  File "/opt/homebrew/Cellar/python@3.14/3.14.0/Frameworks/Python.framework/Versions/3.14/lib/python3.14/threading.py", line 1023, in run
    self._target(*self._args, **self._kwargs)
    ~~~~~~~~~~~~^^^^^^^^^^^^^^^^^^^^^^^^^^^^^
  File "/Users/angeport/Documents/GitHub/Group-Navigation/.venv/lib/python3.14/site-packages/socketio/server.py", line 594, in _handle_event_internal
    r = server._trigger_event(data[0], namespace, sid, *data[1:])
  File "/Users/angeport/Documents/GitHub/Group-Navigation/.venv/lib/python3.14/site-packages/socketio/server.py", line 620, in _trigger_event
    return handler(*args)
  File "/Users/angeport/Documents/GitHub/Group-Navigation/.venv/lib/python3.14/site-packages/flask_socketio/__init__.py", line 292, in _handler
    return self._handle_event(handler, message, real_ns, sid,
           ~~~~~~~~~~~~~~~~~~^^^^^^^^^^^^^^^^^^^^^^^^^^^^^^^^
                              *args)
                              ^^^^^^
  File "/Users/angeport/Documents/GitHub/Group-Navigation/.venv/lib/python3.14/site-packages/flask_socketio/__init__.py", line 835, in _handle_event
    ret = handler(*args)
  File "/Users/angeport/Documents/GitHub/Group-Navigation/routes.py", line 763, in on_join_tracking
    sio.emit('user_count', len(connected_users), broadcast=True)
    ~~~~~~~~^^^^^^^^^^^^^^^^^^^^^^^^^^^^^^^^^^^^^^^^^^^^^^^^^^^^
  File "/Users/angeport/Documents/GitHub/Group-Navigation/.venv/lib/python3.14/site-packages/flask_socketio/__init__.py", line 472, in emit
    self.server.emit(event, *args, namespace=namespace, to=to,
    ~~~~~~~~~~~~~~~~^^^^^^^^^^^^^^^^^^^^^^^^^^^^^^^^^^^^^^^^^^
                     skip_sid=skip_sid, callback=callback, **kwargs)
                     ^^^^^^^^^^^^^^^^^^^^^^^^^^^^^^^^^^^^^^^^^^^^^^^
TypeError: Server.emit() got an unexpected keyword argument 'broadcast'
Exception in thread Thread-43 (_handle_event_internal):
Traceback (most recent call last):
  File "/opt/homebrew/Cellar/python@3.14/3.14.0/Frameworks/Python.framework/Versions/3.14/lib/python3.14/threading.py", line 1081, in _bootstrap_inner
    self._context.run(self.run)
    ~~~~~~~~~~~~~~~~~^^^^^^^^^^
  File "/opt/homebrew/Cellar/python@3.14/3.14.0/Frameworks/Python.framework/Versions/3.14/lib/python3.14/threading.py", line 1023, in run
    self._target(*self._args, **self._kwargs)
    ~~~~~~~~~~~~^^^^^^^^^^^^^^^^^^^^^^^^^^^^^
  File "/Users/angeport/Documents/GitHub/Group-Navigation/.venv/lib/python3.14/site-packages/socketio/server.py", line 594, in _handle_event_internal
    r = server._trigger_event(data[0], namespace, sid, *data[1:])
  File "/Users/angeport/Documents/GitHub/Group-Navigation/.venv/lib/python3.14/site-packages/socketio/server.py", line 620, in _trigger_event
    return handler(*args)
  File "/Users/angeport/Documents/GitHub/Group-Navigation/.venv/lib/python3.14/site-packages/flask_socketio/__init__.py", line 292, in _handler
    return self._handle_event(handler, message, real_ns, sid,
           ~~~~~~~~~~~~~~~~~~^^^^^^^^^^^^^^^^^^^^^^^^^^^^^^^^
                              *args)
                              ^^^^^^
  File "/Users/angeport/Documents/GitHub/Group-Navigation/.venv/lib/python3.14/site-packages/flask_socketio/__init__.py", line 835, in _handle_event
    ret = handler(*args)
  File "/Users/angeport/Documents/GitHub/Group-Navigation/routes.py", line 801, in on_update_location
    sio.emit('location_update', {
    ~~~~~~~~^^^^^^^^^^^^^^^^^^^^^
        'user_id': user_id,
        ^^^^^^^^^^^^^^^^^^^
    ...<3 lines>...
        'longitude': longitude
        ^^^^^^^^^^^^^^^^^^^^^^
    }, broadcast=True)
    ^^^^^^^^^^^^^^^^^^
  File "/Users/angeport/Documents/GitHub/Group-Navigation/.venv/lib/python3.14/site-packages/flask_socketio/__init__.py", line 472, in emit
    self.server.emit(event, *args, namespace=namespace, to=to,
    ~~~~~~~~~~~~~~~~^^^^^^^^^^^^^^^^^^^^^^^^^^^^^^^^^^^^^^^^^^
                     skip_sid=skip_sid, callback=callback, **kwargs)
                     ^^^^^^^^^^^^^^^^^^^^^^^^^^^^^^^^^^^^^^^^^^^^^^^
TypeError: Server.emit() got an unexpected keyword argument 'broadcast'
Exception in thread Thread-44 (_handle_event_internal):
Traceback (most recent call last):
  File "/opt/homebrew/Cellar/python@3.14/3.14.0/Frameworks/Python.framework/Versions/3.14/lib/python3.14/threading.py", line 1081, in _bootstrap_inner
    self._context.run(self.run)
    ~~~~~~~~~~~~~~~~~^^^^^^^^^^
  File "/opt/homebrew/Cellar/python@3.14/3.14.0/Frameworks/Python.framework/Versions/3.14/lib/python3.14/threading.py", line 1023, in run
    self._target(*self._args, **self._kwargs)
    ~~~~~~~~~~~~^^^^^^^^^^^^^^^^^^^^^^^^^^^^^
  File "/Users/angeport/Documents/GitHub/Group-Navigation/.venv/lib/python3.14/site-packages/socketio/server.py", line 594, in _handle_event_internal
    r = server._trigger_event(data[0], namespace, sid, *data[1:])
  File "/Users/angeport/Documents/GitHub/Group-Navigation/.venv/lib/python3.14/site-packages/socketio/server.py", line 620, in _trigger_event
    return handler(*args)
  File "/Users/angeport/Documents/GitHub/Group-Navigation/.venv/lib/python3.14/site-packages/flask_socketio/__init__.py", line 292, in _handler
    return self._handle_event(handler, message, real_ns, sid,
           ~~~~~~~~~~~~~~~~~~^^^^^^^^^^^^^^^^^^^^^^^^^^^^^^^^
                              *args)
                              ^^^^^^
  File "/Users/angeport/Documents/GitHub/Group-Navigation/.venv/lib/python3.14/site-packages/flask_socketio/__init__.py", line 835, in _handle_event
    ret = handler(*args)
  File "/Users/angeport/Documents/GitHub/Group-Navigation/routes.py", line 801, in on_update_location
    sio.emit('location_update', {
    ~~~~~~~~^^^^^^^^^^^^^^^^^^^^^
        'user_id': user_id,
        ^^^^^^^^^^^^^^^^^^^
    ...<3 lines>...
        'longitude': longitude
        ^^^^^^^^^^^^^^^^^^^^^^
    }, broadcast=True)
    ^^^^^^^^^^^^^^^^^^
  File "/Users/angeport/Documents/GitHub/Group-Navigation/.venv/lib/python3.14/site-packages/flask_socketio/__init__.py", line 472, in emit
    self.server.emit(event, *args, namespace=namespace, to=to,
    ~~~~~~~~~~~~~~~~^^^^^^^^^^^^^^^^^^^^^^^^^^^^^^^^^^^^^^^^^^
                     skip_sid=skip_sid, callback=callback, **kwargs)
                     ^^^^^^^^^^^^^^^^^^^^^^^^^^^^^^^^^^^^^^^^^^^^^^^
TypeError: Server.emit() got an unexpected keyword argument 'broadcast'
Exception in thread Thread-46 (_handle_event_internal):
Traceback (most recent call last):
  File "/opt/homebrew/Cellar/python@3.14/3.14.0/Frameworks/Python.framework/Versions/3.14/lib/python3.14/threading.py", line 1081, in _bootstrap_inner
    self._context.run(self.run)
    ~~~~~~~~~~~~~~~~~^^^^^^^^^^
  File "/opt/homebrew/Cellar/python@3.14/3.14.0/Frameworks/Python.framework/Versions/3.14/lib/python3.14/threading.py", line 1023, in run
    self._target(*self._args, **self._kwargs)
    ~~~~~~~~~~~~^^^^^^^^^^^^^^^^^^^^^^^^^^^^^
  File "/Users/angeport/Documents/GitHub/Group-Navigation/.venv/lib/python3.14/site-packages/socketio/server.py", line 594, in _handle_event_internal
    r = server._trigger_event(data[0], namespace, sid, *data[1:])
  File "/Users/angeport/Documents/GitHub/Group-Navigation/.venv/lib/python3.14/site-packages/socketio/server.py", line 620, in _trigger_event
    return handler(*args)
  File "/Users/angeport/Documents/GitHub/Group-Navigation/.venv/lib/python3.14/site-packages/flask_socketio/__init__.py", line 292, in _handler
    return self._handle_event(handler, message, real_ns, sid,
           ~~~~~~~~~~~~~~~~~~^^^^^^^^^^^^^^^^^^^^^^^^^^^^^^^^
                              *args)
                              ^^^^^^
  File "/Users/angeport/Documents/GitHub/Group-Navigation/.venv/lib/python3.14/site-packages/flask_socketio/__init__.py", line 835, in _handle_event
    ret = handler(*args)
  File "/Users/angeport/Documents/GitHub/Group-Navigation/routes.py", line 801, in on_update_location
    sio.emit('location_update', {
    ~~~~~~~~^^^^^^^^^^^^^^^^^^^^^
        'user_id': user_id,
        ^^^^^^^^^^^^^^^^^^^
    ...<3 lines>...
        'longitude': longitude
        ^^^^^^^^^^^^^^^^^^^^^^
    }, broadcast=True)
    ^^^^^^^^^^^^^^^^^^
  File "/Users/angeport/Documents/GitHub/Group-Navigation/.venv/lib/python3.14/site-packages/flask_socketio/__init__.py", line 472, in emit
    self.server.emit(event, *args, namespace=namespace, to=to,
    ~~~~~~~~~~~~~~~~^^^^^^^^^^^^^^^^^^^^^^^^^^^^^^^^^^^^^^^^^^
                     skip_sid=skip_sid, callback=callback, **kwargs)
                     ^^^^^^^^^^^^^^^^^^^^^^^^^^^^^^^^^^^^^^^^^^^^^^^
TypeError: Server.emit() got an unexpected keyword argument 'broadcast'
Exception in thread Thread-45 (_handle_event_internal):
Traceback (most recent call last):
  File "/opt/homebrew/Cellar/python@3.14/3.14.0/Frameworks/Python.framework/Versions/3.14/lib/python3.14/threading.py", line 1081, in _bootstrap_inner
    self._context.run(self.run)
    ~~~~~~~~~~~~~~~~~^^^^^^^^^^
  File "/opt/homebrew/Cellar/python@3.14/3.14.0/Frameworks/Python.framework/Versions/3.14/lib/python3.14/threading.py", line 1023, in run
    self._target(*self._args, **self._kwargs)
    ~~~~~~~~~~~~^^^^^^^^^^^^^^^^^^^^^^^^^^^^^
  File "/Users/angeport/Documents/GitHub/Group-Navigation/.venv/lib/python3.14/site-packages/socketio/server.py", line 594, in _handle_event_internal
    r = server._trigger_event(data[0], namespace, sid, *data[1:])
  File "/Users/angeport/Documents/GitHub/Group-Navigation/.venv/lib/python3.14/site-packages/socketio/server.py", line 620, in _trigger_event
    return handler(*args)
  File "/Users/angeport/Documents/GitHub/Group-Navigation/.venv/lib/python3.14/site-packages/flask_socketio/__init__.py", line 292, in _handler
    return self._handle_event(handler, message, real_ns, sid,
           ~~~~~~~~~~~~~~~~~~^^^^^^^^^^^^^^^^^^^^^^^^^^^^^^^^
                              *args)
                              ^^^^^^
  File "/Users/angeport/Documents/GitHub/Group-Navigation/.venv/lib/python3.14/site-packages/flask_socketio/__init__.py", line 835, in _handle_event
    ret = handler(*args)
  File "/Users/angeport/Documents/GitHub/Group-Navigation/routes.py", line 801, in on_update_location
    sio.emit('location_update', {
    ~~~~~~~~^^^^^^^^^^^^^^^^^^^^^
        'user_id': user_id,
        ^^^^^^^^^^^^^^^^^^^
    ...<3 lines>...
        'longitude': longitude
        ^^^^^^^^^^^^^^^^^^^^^^
    }, broadcast=True)
    ^^^^^^^^^^^^^^^^^^
  File "/Users/angeport/Documents/GitHub/Group-Navigation/.venv/lib/python3.14/site-packages/flask_socketio/__init__.py", line 472, in emit
    self.server.emit(event, *args, namespace=namespace, to=to,
    ~~~~~~~~~~~~~~~~^^^^^^^^^^^^^^^^^^^^^^^^^^^^^^^^^^^^^^^^^^
                     skip_sid=skip_sid, callback=callback, **kwargs)
                     ^^^^^^^^^^^^^^^^^^^^^^^^^^^^^^^^^^^^^^^^^^^^^^^
TypeError: Server.emit() got an unexpected keyword argument 'broadcast'
disconnect handler error
Traceback (most recent call last):
  File "/Users/angeport/Documents/GitHub/Group-Navigation/.venv/lib/python3.14/site-packages/socketio/server.py", line 620, in _trigger_event
    return handler(*args)
  File "/Users/angeport/Documents/GitHub/Group-Navigation/.venv/lib/python3.14/site-packages/flask_socketio/__init__.py", line 292, in _handler
    return self._handle_event(handler, message, real_ns, sid,
           ~~~~~~~~~~~~~~~~~~^^^^^^^^^^^^^^^^^^^^^^^^^^^^^^^^
                              *args)
                              ^^^^^^
  File "/Users/angeport/Documents/GitHub/Group-Navigation/.venv/lib/python3.14/site-packages/flask_socketio/__init__.py", line 835, in _handle_event
    ret = handler(*args)
TypeError: init_socketio.<locals>.on_disconnect() takes 0 positional arguments but 1 was given

During handling of the above exception, another exception occurred:

Traceback (most recent call last):
  File "/Users/angeport/Documents/GitHub/Group-Navigation/.venv/lib/python3.14/site-packages/engineio/server.py", line 450, in run_handler
    return self.handlers[event](*args)
           ~~~~~~~~~~~~~~~~~~~~^^^^^^^
  File "/Users/angeport/Documents/GitHub/Group-Navigation/.venv/lib/python3.14/site-packages/socketio/server.py", line 674, in _handle_eio_disconnect
    self._handle_disconnect(eio_sid, n, reason)
    ~~~~~~~~~~~~~~~~~~~~~~~^^^^^^^^^^^^^^^^^^^^
  File "/Users/angeport/Documents/GitHub/Group-Navigation/.venv/lib/python3.14/site-packages/socketio/server.py", line 571, in _handle_disconnect
    self._trigger_event('disconnect', namespace, sid,
    ~~~~~~~~~~~~~~~~~~~^^^^^^^^^^^^^^^^^^^^^^^^^^^^^^
                        reason or self.reason.CLIENT_DISCONNECT)
                        ^^^^^^^^^^^^^^^^^^^^^^^^^^^^^^^^^^^^^^^^
  File "/Users/angeport/Documents/GitHub/Group-Navigation/.venv/lib/python3.14/site-packages/socketio/server.py", line 624, in _trigger_event
    return handler(*args[:-1])
  File "/Users/angeport/Documents/GitHub/Group-Navigation/.venv/lib/python3.14/site-packages/flask_socketio/__init__.py", line 292, in _handler
    return self._handle_event(handler, message, real_ns, sid,
           ~~~~~~~~~~~~~~~~~~^^^^^^^^^^^^^^^^^^^^^^^^^^^^^^^^
                              *args)
                              ^^^^^^
  File "/Users/angeport/Documents/GitHub/Group-Navigation/.venv/lib/python3.14/site-packages/flask_socketio/__init__.py", line 835, in _handle_event
    ret = handler(*args)
  File "/Users/angeport/Documents/GitHub/Group-Navigation/routes.py", line 826, in on_disconnect
    sio.emit('user_count', len(connected_users), broadcast=True)
    ~~~~~~~~^^^^^^^^^^^^^^^^^^^^^^^^^^^^^^^^^^^^^^^^^^^^^^^^^^^^
  File "/Users/angeport/Documents/GitHub/Group-Navigation/.venv/lib/python3.14/site-packages/flask_socketio/__init__.py", line 472, in emit
    self.server.emit(event, *args, namespace=namespace, to=to,
    ~~~~~~~~~~~~~~~~^^^^^^^^^^^^^^^^^^^^^^^^^^^^^^^^^^^^^^^^^^
                     skip_sid=skip_sid, callback=callback, **kwargs)
                     ^^^^^^^^^^^^^^^^^^^^^^^^^^^^^^^^^^^^^^^^^^^^^^^
TypeError: Server.emit() got an unexpected keyword argument 'broadcast'

During handling of the above exception, another exception occurred:

Traceback (most recent call last):
  File "/Users/angeport/Documents/GitHub/Group-Navigation/.venv/lib/python3.14/site-packages/engineio/server.py", line 456, in run_handler
    return self.handlers[event](args[0])
           ~~~~~~~~~~~~~~~~~~~~^^^^^^^^^
TypeError: Server._handle_eio_disconnect() missing 1 required positional argument: 'reason'
127.0.0.1 - - [29/Oct/2025 19:09:47] "GET /socket.io/?EIO=4&transport=websocket&sid=ji8KDF6qjdcXkyCuAAAC HTTP/1.1" 200 -
127.0.0.1 - - [29/Oct/2025 19:09:47] "GET /profiles/login HTTP/1.1" 200 -
127.0.0.1 - - [29/Oct/2025 19:09:53] "[32mPOST /profiles/login HTTP/1.1[0m" 302 -
127.0.0.1 - - [29/Oct/2025 19:09:53] "GET /profiles/map HTTP/1.1" 200 -
127.0.0.1 - - [29/Oct/2025 19:09:53] "GET /socket.io/?EIO=4&transport=polling&t=PepXRbD HTTP/1.1" 200 -
127.0.0.1 - - [29/Oct/2025 19:09:53] "POST /socket.io/?EIO=4&transport=polling&t=PepXRbL&sid=6nSoV9jWRQY756ObAAAE HTTP/1.1" 200 -
127.0.0.1 - - [29/Oct/2025 19:09:53] "GET /socket.io/?EIO=4&transport=polling&t=PepXRbM&sid=6nSoV9jWRQY756ObAAAE HTTP/1.1" 200 -
Exception in thread Thread-57 (_handle_event_internal):
Traceback (most recent call last):
  File "/opt/homebrew/Cellar/python@3.14/3.14.0/Frameworks/Python.framework/Versions/3.14/lib/python3.14/threading.py", line 1081, in _bootstrap_inner
    self._context.run(self.run)
    ~~~~~~~~~~~~~~~~~^^^^^^^^^^
  File "/opt/homebrew/Cellar/python@3.14/3.14.0/Frameworks/Python.framework/Versions/3.14/lib/python3.14/threading.py", line 1023, in run
    self._target(*self._args, **self._kwargs)
    ~~~~~~~~~~~~^^^^^^^^^^^^^^^^^^^^^^^^^^^^^
  File "/Users/angeport/Documents/GitHub/Group-Navigation/.venv/lib/python3.14/site-packages/socketio/server.py", line 594, in _handle_event_internal
    r = server._trigger_event(data[0], namespace, sid, *data[1:])
  File "/Users/angeport/Documents/GitHub/Group-Navigation/.venv/lib/python3.14/site-packages/socketio/server.py", line 620, in _trigger_event
    return handler(*args)
  File "/Users/angeport/Documents/GitHub/Group-Navigation/.venv/lib/python3.14/site-packages/flask_socketio/__init__.py", line 292, in _handler
    return self._handle_event(handler, message, real_ns, sid,
           ~~~~~~~~~~~~~~~~~~^^^^^^^^^^^^^^^^^^^^^^^^^^^^^^^^
                              *args)
                              ^^^^^^
  File "/Users/angeport/Documents/GitHub/Group-Navigation/.venv/lib/python3.14/site-packages/flask_socketio/__init__.py", line 835, in _handle_event
    ret = handler(*args)
  File "/Users/angeport/Documents/GitHub/Group-Navigation/routes.py", line 763, in on_join_tracking
    sio.emit('user_count', len(connected_users), broadcast=True)
    ~~~~~~~~^^^^^^^^^^^^^^^^^^^^^^^^^^^^^^^^^^^^^^^^^^^^^^^^^^^^
  File "/Users/angeport/Documents/GitHub/Group-Navigation/.venv/lib/python3.14/site-packages/flask_socketio/__init__.py", line 472, in emit
    self.server.emit(event, *args, namespace=namespace, to=to,
    ~~~~~~~~~~~~~~~~^^^^^^^^^^^^^^^^^^^^^^^^^^^^^^^^^^^^^^^^^^
                     skip_sid=skip_sid, callback=callback, **kwargs)
                     ^^^^^^^^^^^^^^^^^^^^^^^^^^^^^^^^^^^^^^^^^^^^^^^
TypeError: Server.emit() got an unexpected keyword argument 'broadcast'
Exception in thread Thread-58 (_handle_event_internal):
Exception in thread Thread-59 (_handle_event_internal):
Traceback (most recent call last):
  File "/opt/homebrew/Cellar/python@3.14/3.14.0/Frameworks/Python.framework/Versions/3.14/lib/python3.14/threading.py", line 1081, in _bootstrap_inner
    self._context.run(self.run)
    ~~~~~~~~~~~~~~~~~^^^^^^^^^^
  File "/opt/homebrew/Cellar/python@3.14/3.14.0/Frameworks/Python.framework/Versions/3.14/lib/python3.14/threading.py", line 1023, in run
    self._target(*self._args, **self._kwargs)
    ~~~~~~~~~~~~^^^^^^^^^^^^^^^^^^^^^^^^^^^^^
  File "/Users/angeport/Documents/GitHub/Group-Navigation/.venv/lib/python3.14/site-packages/socketio/server.py", line 594, in _handle_event_internal
    r = server._trigger_event(data[0], namespace, sid, *data[1:])
  File "/Users/angeport/Documents/GitHub/Group-Navigation/.venv/lib/python3.14/site-packages/socketio/server.py", line 620, in _trigger_event
    return handler(*args)
  File "/Users/angeport/Documents/GitHub/Group-Navigation/.venv/lib/python3.14/site-packages/flask_socketio/__init__.py", line 292, in _handler
    return self._handle_event(handler, message, real_ns, sid,
           ~~~~~~~~~~~~~~~~~~^^^^^^^^^^^^^^^^^^^^^^^^^^^^^^^^
                              *args)
                              ^^^^^^
  File "/Users/angeport/Documents/GitHub/Group-Navigation/.venv/lib/python3.14/site-packages/flask_socketio/__init__.py", line 835, in _handle_event
    ret = handler(*args)
  File "/Users/angeport/Documents/GitHub/Group-Navigation/routes.py", line 801, in on_update_location
    sio.emit('location_update', {
    ~~~~~~~~^^^^^^^^^^^^^^^^^^^^^
        'user_id': user_id,
        ^^^^^^^^^^^^^^^^^^^
    ...<3 lines>...
        'longitude': longitude
        ^^^^^^^^^^^^^^^^^^^^^^
    }, broadcast=True)
    ^^^^^^^^^^^^^^^^^^
  File "/Users/angeport/Documents/GitHub/Group-Navigation/.venv/lib/python3.14/site-packages/flask_socketio/__init__.py", line 472, in emit
    self.server.emit(event, *args, namespace=namespace, to=to,
    ~~~~~~~~~~~~~~~~^^^^^^^^^^^^^^^^^^^^^^^^^^^^^^^^^^^^^^^^^^
                     skip_sid=skip_sid, callback=callback, **kwargs)
                     ^^^^^^^^^^^^^^^^^^^^^^^^^^^^^^^^^^^^^^^^^^^^^^^
TypeError: Server.emit() got an unexpected keyword argument 'broadcast'
Traceback (most recent call last):
  File "/opt/homebrew/Cellar/python@3.14/3.14.0/Frameworks/Python.framework/Versions/3.14/lib/python3.14/threading.py", line 1081, in _bootstrap_inner
    self._context.run(self.run)
    ~~~~~~~~~~~~~~~~~^^^^^^^^^^
  File "/opt/homebrew/Cellar/python@3.14/3.14.0/Frameworks/Python.framework/Versions/3.14/lib/python3.14/threading.py", line 1023, in run
    self._target(*self._args, **self._kwargs)
    ~~~~~~~~~~~~^^^^^^^^^^^^^^^^^^^^^^^^^^^^^
  File "/Users/angeport/Documents/GitHub/Group-Navigation/.venv/lib/python3.14/site-packages/socketio/server.py", line 594, in _handle_event_internal
    r = server._trigger_event(data[0], namespace, sid, *data[1:])
  File "/Users/angeport/Documents/GitHub/Group-Navigation/.venv/lib/python3.14/site-packages/socketio/server.py", line 620, in _trigger_event
    return handler(*args)
  File "/Users/angeport/Documents/GitHub/Group-Navigation/.venv/lib/python3.14/site-packages/flask_socketio/__init__.py", line 292, in _handler
    return self._handle_event(handler, message, real_ns, sid,
           ~~~~~~~~~~~~~~~~~~^^^^^^^^^^^^^^^^^^^^^^^^^^^^^^^^
                              *args)
                              ^^^^^^
  File "/Users/angeport/Documents/GitHub/Group-Navigation/.venv/lib/python3.14/site-packages/flask_socketio/__init__.py", line 835, in _handle_event
    ret = handler(*args)
  File "/Users/angeport/Documents/GitHub/Group-Navigation/routes.py", line 801, in on_update_location
    sio.emit('location_update', {
    ~~~~~~~~^^^^^^^^^^^^^^^^^^^^^
        'user_id': user_id,
        ^^^^^^^^^^^^^^^^^^^
    ...<3 lines>...
        'longitude': longitude
        ^^^^^^^^^^^^^^^^^^^^^^
    }, broadcast=True)
    ^^^^^^^^^^^^^^^^^^
  File "/Users/angeport/Documents/GitHub/Group-Navigation/.venv/lib/python3.14/site-packages/flask_socketio/__init__.py", line 472, in emit
    self.server.emit(event, *args, namespace=namespace, to=to,
    ~~~~~~~~~~~~~~~~^^^^^^^^^^^^^^^^^^^^^^^^^^^^^^^^^^^^^^^^^^
                     skip_sid=skip_sid, callback=callback, **kwargs)
                     ^^^^^^^^^^^^^^^^^^^^^^^^^^^^^^^^^^^^^^^^^^^^^^^
TypeError: Server.emit() got an unexpected keyword argument 'broadcast'
Exception in thread Thread-60 (_handle_event_internal):
Traceback (most recent call last):
  File "/opt/homebrew/Cellar/python@3.14/3.14.0/Frameworks/Python.framework/Versions/3.14/lib/python3.14/threading.py", line 1081, in _bootstrap_inner
    self._context.run(self.run)
    ~~~~~~~~~~~~~~~~~^^^^^^^^^^
  File "/opt/homebrew/Cellar/python@3.14/3.14.0/Frameworks/Python.framework/Versions/3.14/lib/python3.14/threading.py", line 1023, in run
    self._target(*self._args, **self._kwargs)
    ~~~~~~~~~~~~^^^^^^^^^^^^^^^^^^^^^^^^^^^^^
  File "/Users/angeport/Documents/GitHub/Group-Navigation/.venv/lib/python3.14/site-packages/socketio/server.py", line 594, in _handle_event_internal
    r = server._trigger_event(data[0], namespace, sid, *data[1:])
  File "/Users/angeport/Documents/GitHub/Group-Navigation/.venv/lib/python3.14/site-packages/socketio/server.py", line 620, in _trigger_event
    return handler(*args)
  File "/Users/angeport/Documents/GitHub/Group-Navigation/.venv/lib/python3.14/site-packages/flask_socketio/__init__.py", line 292, in _handler
    return self._handle_event(handler, message, real_ns, sid,
           ~~~~~~~~~~~~~~~~~~^^^^^^^^^^^^^^^^^^^^^^^^^^^^^^^^
                              *args)
                              ^^^^^^
  File "/Users/angeport/Documents/GitHub/Group-Navigation/.venv/lib/python3.14/site-packages/flask_socketio/__init__.py", line 835, in _handle_event
    ret = handler(*args)
  File "/Users/angeport/Documents/GitHub/Group-Navigation/routes.py", line 801, in on_update_location
    sio.emit('location_update', {
    ~~~~~~~~^^^^^^^^^^^^^^^^^^^^^
        'user_id': user_id,
        ^^^^^^^^^^^^^^^^^^^
    ...<3 lines>...
        'longitude': longitude
        ^^^^^^^^^^^^^^^^^^^^^^
    }, broadcast=True)
    ^^^^^^^^^^^^^^^^^^
  File "/Users/angeport/Documents/GitHub/Group-Navigation/.venv/lib/python3.14/site-packages/flask_socketio/__init__.py", line 472, in emit
    self.server.emit(event, *args, namespace=namespace, to=to,
    ~~~~~~~~~~~~~~~~^^^^^^^^^^^^^^^^^^^^^^^^^^^^^^^^^^^^^^^^^^
                     skip_sid=skip_sid, callback=callback, **kwargs)
                     ^^^^^^^^^^^^^^^^^^^^^^^^^^^^^^^^^^^^^^^^^^^^^^^
TypeError: Server.emit() got an unexpected keyword argument 'broadcast'
Exception in thread Thread-61 (_handle_event_internal):
Traceback (most recent call last):
  File "/opt/homebrew/Cellar/python@3.14/3.14.0/Frameworks/Python.framework/Versions/3.14/lib/python3.14/threading.py", line 1081, in _bootstrap_inner
    self._context.run(self.run)
    ~~~~~~~~~~~~~~~~~^^^^^^^^^^
  File "/opt/homebrew/Cellar/python@3.14/3.14.0/Frameworks/Python.framework/Versions/3.14/lib/python3.14/threading.py", line 1023, in run
    self._target(*self._args, **self._kwargs)
    ~~~~~~~~~~~~^^^^^^^^^^^^^^^^^^^^^^^^^^^^^
  File "/Users/angeport/Documents/GitHub/Group-Navigation/.venv/lib/python3.14/site-packages/socketio/server.py", line 594, in _handle_event_internal
    r = server._trigger_event(data[0], namespace, sid, *data[1:])
  File "/Users/angeport/Documents/GitHub/Group-Navigation/.venv/lib/python3.14/site-packages/socketio/server.py", line 620, in _trigger_event
    return handler(*args)
  File "/Users/angeport/Documents/GitHub/Group-Navigation/.venv/lib/python3.14/site-packages/flask_socketio/__init__.py", line 292, in _handler
    return self._handle_event(handler, message, real_ns, sid,
           ~~~~~~~~~~~~~~~~~~^^^^^^^^^^^^^^^^^^^^^^^^^^^^^^^^
                              *args)
                              ^^^^^^
  File "/Users/angeport/Documents/GitHub/Group-Navigation/.venv/lib/python3.14/site-packages/flask_socketio/__init__.py", line 835, in _handle_event
    ret = handler(*args)
  File "/Users/angeport/Documents/GitHub/Group-Navigation/routes.py", line 801, in on_update_location
    sio.emit('location_update', {
    ~~~~~~~~^^^^^^^^^^^^^^^^^^^^^
        'user_id': user_id,
        ^^^^^^^^^^^^^^^^^^^
    ...<3 lines>...
        'longitude': longitude
        ^^^^^^^^^^^^^^^^^^^^^^
    }, broadcast=True)
    ^^^^^^^^^^^^^^^^^^
  File "/Users/angeport/Documents/GitHub/Group-Navigation/.venv/lib/python3.14/site-packages/flask_socketio/__init__.py", line 472, in emit
    self.server.emit(event, *args, namespace=namespace, to=to,
    ~~~~~~~~~~~~~~~~^^^^^^^^^^^^^^^^^^^^^^^^^^^^^^^^^^^^^^^^^^
                     skip_sid=skip_sid, callback=callback, **kwargs)
                     ^^^^^^^^^^^^^^^^^^^^^^^^^^^^^^^^^^^^^^^^^^^^^^^
TypeError: Server.emit() got an unexpected keyword argument 'broadcast'
